Workbook

Sheet RANKING
A1: Nr | B1: Imię i nazwisko: | C1: Punkty
A2: 1 | B2: Monika Bugajska | C2: =+'Monika Bugajska'!M76 -> 223
A3: 2 | B3: Konrad Pucułek | C3: =+'Konrad Pucułek'!M76 -> 199
A4: 3 | B4: Marek Szóstkiewicz | C4: =+'Marek Szóstkiewicz'!M76 -> 197
A5: 4 | B5: Mariusz Tarnowski | C5: =+'Mariusz Tarnowski'!M76 -> 196
A6: 5 | B6: Milena Strąk-Małecka | C6: =+'Milena Strąk-Małecka'!M76 -> 181
A7: 6 | B7: Marcin Czarnecki | C7: =+'Marcin Czarnecki'!M76 -> 180
A8: 7 | B8: Cezary Strąk | C8: =+'Cezary Strąk'!M76 -> 179
A9: 8 | B9: Adrian Strąk | C9: =+'Adrian Strąk'!M76 -> 175
A10: 9 | B10: Łukasz Ostrowski | C10: =+'Łukasz Ostrowski'!M76 -> 174
A11: 10 | B11: Grzegorz Cieślak | C11: =+'Grzegorz Cieślak'!M76 -> 170
A12: 11 | B12: Wojtek Zawisza | C12: =+'Wojtek Zawisza'!M76 -> 169
A13: 12 | B13: Marcin Kupisz | C13: =+'Marcin Kupisz'!M76 -> 166
A14: 13 | B14: Marcin Żyterski | C14: =+'Marcin Żyterski'!M76 -> 159
A15: 14 | B15: Roman Kalinowski | C15: =+'Roman Kalinowski'!M76 -> 151
B16: Grzegorz Filipowicz | C16: =+'Grzegorz Filipowicz'!M76 -> 141

Sheet Adrian Strąk
A1: Imię i nazwisko: Adrian Strąk
A2: Typ na mistrza EURO 2024: | E2: Niemcy
F3: FAZA GRUPOWA | I3: Król strzelców: | L3: Harry Kane
I4: Liczba goli: | L4: 7
A5: Data | B5: Godzina | F5: Typ | J5: Wynik meczu | M5: Liczba punktów
F6: Grupa A
A7: 14.06 | B7: 0.875 | D7: Niemcy | E7: 2 | F7: : | G7: 0 | H7: Szkocja | J7: 5 | K7: : | L7: 1 | M7: 3
A8: 15.06 | B8: 0.625 | D8: Węgry | E8: 1 | F8: : | G8: 2 | H8: Szwajcaria | J8: 1 | K8: : | L8: 3 | M8: 4
A9: 19.06 | B9: 0.75 | D9: Niemcy | E9: 2 | F9: : | G9: 0 | H9: Węgry | J9: 2 | K9: : | L9: 0 | M9: 6
A10: 19.06 | B10: 0.875 | D10: Szkocja | E10: 0 | F10: : | G10: 1 | H10: Szwajcaria | J10: 1 | K10: : | L10: 1 | M10: 1
A11: 23.06 | B11: 0.875 | D11: Szwajcaria | E11: 1 | F11: : | G11: 2 | H11: Niemcy | J11: 1 | K11: : | L11: 1 | M11: 1
A12: 23.06 | B12: 0.875 | D12: Szkocja | E12: 1 | F12: : | G12: 0 | H12: Węgry | J12: 0 | K12: : | L12: 1 | M12: 0
F14: Grupa B
A15: 15.06 | B15: 0.75 | D15: Hiszpania | E15: 2 | F15: : | G15: 1 | H15: Chorwacja | J15: 3 | K15: : | L15: 0 | M15: 3
A16: 15.06 | B16: 0.875 | D16: Włochy | E16: 2 | F16: : | G16: 0 | H16: Albania | J16: 2 | K16: : | L16: 1 | M16: 4
A17: 19.06 | B17: 0.625 | D17: Chorwacja | E17: 1 | F17: : | G17: 0 | H17: Albania | J17: 2 | K17: : | L17: 2 | M17: 0
A18: 20.06 | B18: 0.875 | D18: Hiszpania | E18: 1 | F18: : | G18: 1 | H18: Włochy | J18: 1 | K18: : | L18: 0 | M18: 1
A19: 24.06 | B19: 0.875 | D19: Albania | E19: 1 | F19: : | G19: 4 | H19: Hiszpania | J19: 0 | K19: : | L19: 1 | M19: 3
A20: 24.06 | B20: 0.875 | D20: Chorwacja | E20: 1 | F20: : | G20: 1 | H20: Włochy | J20: 1 | K20: : | L20: 1 | M20: 6
F22: Grupa C
A23: 16.06 | B23: 0.75 | D23: Słowenia | E23: 1 | F23: : | G23: 3 | H23: Dania | J23: 1 | K23: : | L23: 1 | M23: 1
A24: 16.06 | B24: 0.875 | D24: Serbia | E24: 0 | F24: : | G24: 2 | H24: Anglia | J24: 0 | K24: : | L24: 1 | M24: 4
A25: 20.06 | B25: 0.625 | D25: Słowenia | E25: 1 | F25: : | G25: 2 | H25: Serbia | J25: 1 | K25: : | L25: 1 | M25: 1
A26: 20.06 | B26: 0.75 | D26: Dania | E26: 0 | F26: : | G26: 3 | H26: Anglia | J26: 1 | K26: : | L26: 1 | M26: 0
A27: 25.06 | B27: 0.875 | D27: Angia | E27: 3 | F27: : | G27: 0 | H27: Słowenia | J27: 0 | K27: : | L27: 0 | M27: 1
A28: 25.06 | B28: 0.875 | D28: Dania | E28: 2 | F28: : | G28: 1 | H28: Serbia | J28: 0 | K28: : | L28: 0 | M28: 0
F30: Grupa D
A31: 16.06 | B31: 0.625 | D31: Polska | E31: 0 | F31: : | G31: 2 | H31: Holandia | J31: 1 | K31: : | L31: 2 | M31: 9
A32: 17.06 | B32: 0.875 | D32: Austria | E32: 1 | F32: : | G32: 3 | H32: Francja | J32: 0 | K32: : | L32: 1 | M32: 3
A33: 21.06 | B33: 0.75 | D33: Polska | E33: 1 | F33: : | G33: 1 | H33: Austria | J33: 1 | K33: : | L33: 3 | M33: 1
A34: 21.06 | B34: 0.875 | D34: Holandia | E34: 1 | F34: : | G34: 2 | H34: Francja | J34: 0 | K34: : | L34: 0 | M34: 0
A35: 25.06 | B35: 0.75 | D35: Holandia | E35: 2 | F35: : | G35: 1 | H35: Austria | J35: 2 | K35: : | L35: 3 | M35: 1
A36: 25.06 | B36: 0.75 | D36: Francja | E36: 3 | F36: : | G36: 0 | H36: Polska | J36: 1 | K36: : | L36: 1 | M36: 0
F38: Grupa E
A39: 17.06 | B39: 0.625 | D39: Rumunia | E39: 1 | F39: : | G39: 2 | H39: Ukraina | J39: 3 | K39: : | L39: 0 | M39: 0
A40: 17.06 | B40: 0.75 | D40: Belgia | E40: 2 | F40: : | G40: 1 | H40: Słowacja | J40: 0 | K40: : | L40: 1 | M40: 1
A41: 21.06 | B41: 0.625 | D41: Słowacja | E41: 1 | F41: : | G41: 1 | H41: Ukraina | J41: 1 | K41: : | L41: 2 | M41: 1
A42: 22.06 | B42: 0.875 | D42: Belgia | E42: 2 | F42: : | G42: 0 | H42: Rumunia | J42: 2 | K42: : | L42: 0 | M42: 6
A43: 26.06 | B43: 0.75 | D43: Słowacja | E43: 1 | F43: : | G43: 1 | H43: Rumunia | J43: 1 | K43: : | L43: 1 | M43: 6
A44: 26.06 | B44: 0.75 | D44: Ukraina | E44: 1 | F44: : | G44: 2 | H44: Belgia | J44: 0 | K44: : | L44: 0 | M44: 0
...

Sheet Wojtek Zawisza
A1: Imię i nazwisko: Wojtek Zawisza
A2: Typ na mistrza EURO 2024: | E2: Włochy
F3: FAZA GRUPOWA | I3: Król strzelców: | L3: Mbappe
I4: Liczba goli: | L4: 9
A5: Data | B5: Godzina | F5: Typ | J5: Wynik meczu | M5: Liczba punktów
F6: Grupa A
A7: 14.06 | B7: 0.875 | D7: Niemcy | E7: 3 | F7: : | G7: 1 | H7: Szkocja | J7: 5 | K7: : | L7: 1 | M7: 4
A8: 15.06 | B8: 0.625 | D8: Węgry | E8: 0 | F8: : | G8: 2 | H8: Szwajcaria | J8: 1 | K8: : | L8: 3 | M8: 4
A9: 19.06 | B9: 0.75 | D9: Niemcy | E9: 4 | F9: : | G9: 1 | H9: Węgry | J9: 2 | K9: : | L9: 0 | M9: 3
A10: 19.06 | B10: 0.875 | D10: Szkocja | E10: 1 | F10: : | G10: 2 | H10: Szwajcaria | J10: 1 | K10: : | L10: 1 | M10: 1
A11: 23.06 | B11: 0.875 | D11: Szwajcaria | E11: 1 | F11: : | G11: 3 | H11: Niemcy | J11: 1 | K11: : | L11: 1 | M11: 1
A12: 23.06 | B12: 0.875 | D12: Szkocja | E12: 1 | F12: : | G12: 1 | H12: Węgry | J12: 0 | K12: : | L12: 1 | M12: 1
A15: 15.06 | B15: 0.75 | D15: Hiszpania | E15: 2 | F15: : | G15: 1 | H15: Chorwacja | J15: 3 | K15: : | L15: 0 | M15: 3
A16: 15.06 | B16: 0.875 | D16: Włochy | E16: 2 | F16: : | G16: 0 | H16: Albania | J16: 2 | K16: : | L16: 1 | M16: 4
A17: 19.06 | B17: 0.625 | D17: Chorwacja | E17: 2 | F17: : | G17: 1 | H17: Albania | J17: 2 | K17: : | L17: 2 | M17: 1
A18: 20.06 | B18: 0.875 | D18: Hiszpania | E18: 1 | F18: : | G18: 1 | H18: Włochy | J18: 1 | K18: : | L18: 0 | M18: 1
A19: 24.06 | B19: 0.875 | D19: Albania | E19: 0 | F19: : | G19: 4 | H19: Hiszpania | J19: 0 | K19: : | L19: 1 | M19: 4
A20: 24.06 | B20: 0.875 | D20: Chorwacja | E20: 1 | F20: : | G20: 2 | H20: Włochy | J20: 1 | K20: : | L20: 1 | M20: 1
... A52: 26.06 | B52: 0.875 | D52: Gruzja | E52: 0 | F52: : | G52: 3 | H52: Portugalia | J52: 2 | K52: : | L52: 0 | M52: 0
F55: FAZA PUCHAROWA
F56: 1/8 FINAŁU
A57: 29.06 | B57: 0.75 | D57: Szwajcaria | E57: 0 | F57: : | G57: 1 | H57: Włochy | J57: 2 | K57: : | L57: 0 | M57: 0
A58: 29.06 | B58: 0.875 | D58: Niemcy | E58: 2 | F58: : | G58: 0 | H58: Dania | J58: 2 | K58: : | L58: 0 | M58: 12
A59: 30.06 | B59: 0.75 | D59: Anglia | E59: 1 | F59: : | G59: 0 | H59: Słowacja | J59: 1 | K59: : | L59: 1 | M59: 2
A60: 30.06 | B60: 0.875 | D60: Hiszpania | E60: 2 | F60: : | G60: 0 | H60: Gruzja | J60: 4 | K60: : | L60: 1 | M60: 6
A61: 01.07 | B61: 0.75 | D61: Francja | E61: 1 | F61: : | G61: 1 | H61: Belgia | J61: 1 | K61: : | L61: 0 | M61: 2
A62: 01.07 | B62: 0.875 | D62: Portugalia | E62: 2 | F62: : | G62: 0 | H62: Słowenia | J62: 0 | K62: : | L62: 0 | M62: 2
A63: 02.07 | B63: 0.75 | D63: Rumunia | E63: 1 | F63: : | G63: 2 | H63: Holandia | J63: 0 | K63: : | L63: 3 | M63: 6
A64: 02.07 | B64: 0.875 | D64: Austria | E64: 1 | F64: : | G64: 1 | H64: Turcja | J64: 1 | K64: : | L64: 2 | M64: 2
F65: 1/4 FINAŁU
A66: 05.07 | B66: 0.75 | D66: Hiszpania | E66: 2 | F66: : | G66: 1 | H66: Niemcy | J66: 1 | K66: : | L66: 1 | M66: 2 | O66: =_xlfn.TEXTJOIN(,,"update user_matches set team1_res=",E66,", team2_res=",G66," where match_id=",N66," and user_id= ",$N$65,";") -> update user_matches set team1_res=2, team2_res=1 where match_id= and user_id= ;
A67: 05.07 | B67: 0.875 | D67: Portugalia | E67: 1 | F67: : | G67: 1 | H67: Francja | J67: 0 | K67: : | L67: 0 | M67: 8 | O67: =_xlfn.TEXTJOIN(,,"update user_matches set team1_res=",E67,", team2_res=",G67," where match_id=",N67," and user_id= ",$N$65,";") -> update user_matches set team1_res=1, team2_res=1 where match_id= and user_id= ;
A68: 06.07 | B68: 0.75 | D68: Anglia | E68: 0 | F68: : | G68: 1 | H68: Szwajcaria | J68: 1 | K68: : | L68: 1 | M68: 2 | O68: =_xlfn.TEXTJOIN(,,"update user_matches set team1_res=",E68,", team2_res=",G68," where match_id=",N68," and user_id= ",$N$65,";") -> update user_matches set team1_res=0, team2_res=1 where match_id= and user_id= ;
A69: 06.07 | B69: 0.875 | D69: Holandia | E69: 2 | F69: : | G69: 0 | H69: Turcja | J69: 2 | K69: : | L69: 1 | M69: 8 | O69: =_xlfn.TEXTJOIN(,,"update user_matches set team1_res=",E69,", team2_res=",G69," where match_id=",N69," and user_id= ",$N$65,";") -> update user_matches set team1_res=2, team2_res=0 where match_id= and user_id= ;
F70: 1/2 FINAŁU
A71: 09.07 | B71: 0.875 | D71: Hiszpania | E71: 1 | F71: : | G71: 0 | H71: Francja | J71: 2 | K71: : | L71: 1 | M71: 12 | O71: =_xlfn.TEXTJOIN(,,"update user_matches set team1_res=",E71,", team2_res=",G71," where match_id=",N71," and user_id= ",$N$65,";") -> update user_matches set team1_res=1, team2_res=0 where match_id= and user_id= ;
A72: 10.07 | B72: 0.875 | D72: Holandia | E72: 1 | F72: : | G72: 1 | H72: Anglia | J72: 1 | K72: : | L72: 2 | M72: 3 | O72: =_xlfn.TEXTJOIN(,,"update user_matches set team1_res=",E72,", team2_res=",G72," where match_id=",N72," and user_id= ",$N$65,";") -> update user_matches set team1_res=1, team2_res=1 where match_id= and user_id= ;
F73: FINAŁ
A74: 14.07 | B74: 0.875 | D74: Hiszpania | E74: 2 | F74: : | G74: 1 | H74: Anglia | J74: 2 | K74: : | L74: 1 | M74: 30 | O74: =_xlfn.TEXTJOIN(,,"update user_matches set team1_res=",E74,", team2_res=",G74," where match_id=",N74," and user_id= ",$N$65,";") -> update user_matches set team1_res=2, team2_res=1 where match_id= and user_id= ;
A76: SUMA PUNKTÓW | M76: =SUM(M7:N75) -> 169

Sheet Marcin Żyterski
A1: Imię i nazwisko: Marcin Żyterski
A2: Typ na mistrza EURO 2024: | E2: Włochy
F3: FAZA GRUPOWA | I3: Król strzelców: | L3: Mbappe
I4: Liczba goli: | L4: 7
A5: Data | B5: Godzina | F5: Typ | J5: Wynik meczu | M5: Liczba punktów
F6: Grupa A
A7: 14.06 | B7: 0.875 | D7: Niemcy | E7: 2 | F7: : | G7: 0 | H7: Szkocja | J7: 5 | K7: : | L7: 1 | M7: 3
A8: 15.06 | B8: 0.625 | D8: Węgry | E8: 1 | F8: : | G8: 2 | H8: Szwajcaria | J8: 1 | K8: : | L8: 3 | M8: 4
A9: 19.06 | B9: 0.75 | D9: Niemcy | E9: 3 | F9: : | G9: 0 | H9: Węgry | J9: 2 | K9: : | L9: 0 | M9: 4
A10: 19.06 | B10: 0.875 | D10: Szkocja | E10: 1 | F10: : | G10: 2 | H10: Szwajcaria | J10: 1 | K10: : | L10: 1 | M10: 1
A11: 23.06 | B11: 0.875 | D11: Szwajcaria | E11: 1 | F11: : | G11: 1 | H11: Niemcy | J11: 1 | K11: : | L11: 1 | M11: 6
A12: 23.06 | B12: 0.875 | D12: Szkocja | E12: 2 | F12: : | G12: 1 | H12: Węgry | J12: 0 | K12: : | L12: 1 | M12: 1
F14: Grupa B
A15: 15.06 | B15: 0.75 | D15: Hiszpania | E15: 2 | F15: : | G15: 0 | H15: Chorwacja | J15: 3 | K15: : | L15: 0 | M15: 4
A16: 15.06 | B16: 0.875 | D16: Włochy | E16: 3 | F16: : | G16: 0 | H16: Albania | J16: 2 | K16: : | L16: 1 | M16: 3
A17: 19.06 | B17: 0.625 | D17: Chorwacja | E17: 2 | F17: : | G17: 0 | H17: Albania | J17: 2 | K17: : | L17: 2 | M17: 1
A18: 20.06 | B18: 0.875 | D18: Hiszpania | E18: 1 | F18: : | G18: 1 | H18: Włochy | J18: 1 | K18: : | L18: 0 | M18: 1
A19: 24.06 | B19: 0.875 | D19: Albania | E19: 0 | F19: : | G19: 2 | H19: Hiszpania | J19: 0 | K19: : | L19: 1 | M19: 4
A20: 24.06 | B20: 0.875 | D20: Chorwacja | E20: 1 | F20: : | G20: 2 | H20: Włochy | J20: 1 | K20: : | L20: 1 | M20: 1
F22: Grupa C
A23: 16.06 | B23: 0.75 | D23: Słowania | E23: 0 | F23: : | G23: 2 | H23: Dania | J23: 1 | K23: : | L23: 1 | M23: 0
A24: 16.06 | B24: 0.875 | D24: Serbia | E24: 1 | F24: : | G24: 2 | H24: Anglia | J24: 0 | K24: : | L24: 1 | M24: 4
A25: 20.06 | B25: 0.625 | D25: Słowenia | E25: 1 | F25: : | G25: 1 | H25: Serbia | J25: 1 | K25: : | L25: 1 | M25: 6
A26: 20.06 | B26: 0.75 | D26: Dania | E26: 0 | F26: : | G26: 2 | H26: Anglia | J26: 1 | K26: : | L26: 1 | M26: 0
A27: 25.06 | B27: 0.875 | D27: Angia | E27: 2 | F27: : | G27: 1 | H27: Słowenia | J27: 0 | K27: : | L27: 0 | M27: 0
A28: 25.06 | B28: 0.875 | D28: Dania | E28: 2 | F28: : | G28: 0 | H28: Serbia | J28: 0 | K28: : | L28: 0 | M28: 1
F30: Grupa D
A31: 16.06 | B31: 0.625 | D31: Polska | E31: 0 | F31: : | G31: 3 | H31: Holandia | J31: 1 | K31: : | L31: 2 | M31: 8
A32: 17.06 | B32: 0.875 | D32: Austria | E32: 1 | F32: : | G32: 3 | H32: Francja | J32: 0 | K32: : | L32: 1 | M32: 3
A33: 21.06 | B33: 0.75 | D33: Polska | E33: 2 | F33: : | G33: 1 | H33: Austria | J33: 1 | K33: : | L33: 3 | M33: 0
A34: 21.06 | B34: 0.875 | D34: Holandia | E34: 2 | F34: : | G34: 2 | H34: Francja | J34: 0 | K34: : | L34: 0 | M34: 4
A35: 25.06 | B35: 0.75 | D35: Holandia | E35: 3 | F35: : | G35: 1 | H35: Austria | J35: 2 | K35: : | L35: 3 | M35: 0
A36: 25.06 | B36: 0.75 | D36: Francja | E36: 3 | F36: : | G36: 1 | H36: Polska | J36: 1 | K36: : | L36: 1 | M36: 1
F38: Grupa E
A39: 17.06 | B39: 0.625 | D39: Rumunia | E39: 0 | F39: : | G39: 2 | H39: Ukraina | J39: 3 | K39: : | L39: 0 | M39: 0
A40: 17.06 | B40: 0.75 | D40: Belgia | E40: 4 | F40: : | G40: 0 | H40: Słowacja | J40: 0 | K40: : | L40: 1 | M40: 0
A41: 21.06 | B41: 0.625 | D41: Słowacja | E41: 0 | F41: : | G41: 2 | H41: Ukraina | J41: 1 | K41: : | L41: 2 | M41: 4
A42: 22.06 | B42: 0.875 | D42: Belgia | E42: 2 | F42: : | G42: 0 | H42: Rumunia | J42: 2 | K42: : | L42: 0 | M42: 6
A43: 26.06 | B43: 0.75 | D43: Słowacja | E43: 1 | F43: : | G43: 2 | H43: Rumunia | J43: 1 | K43: : | L43: 1 | M43: 1
A44: 26.06 | B44: 0.75 | D44: Ukraina | E44: 1 | F44: : | G44: 1 | H44: Belgia | J44: 0 | K44: : | L44: 0 | M44: 4
...

Sheet Cezary Strąk
A1: Imię i nazwisko: Cezary Strąk
A2: Typ na mistrza EURO 2024: | E2: Anglia
F3: FAZA GRUPOWA | I3: Król strzelców: | L3: Crystiano Ronaldo
I4: Liczba goli: | L4: 6
A5: Data | B5: Godzina | F5: Typ | J5: Wynik meczu | M5: Liczba punktów
F6: Grupa A
A7: 14.06 | B7: 0.875 | D7: Niemcy | E7: 2 | F7: : | G7: 1 | H7: Szkocja | J7: 5 | K7: : | L7: 1 | M7: 4
A8: 15.06 | B8: 0.625 | D8: Węgry | E8: 0 | F8: : | G8: 1 | H8: Szwajcaria | J8: 1 | K8: : | L8: 3 | M8: 3
A9: 19.06 | B9: 0.75 | D9: Niemcy | E9: 3 | F9: : | G9: 1 | H9: Węgry | J9: 2 | K9: : | L9: 0 | M9: 4
A10: 19.06 | B10: 0.875 | D10: Szkocja | E10: 2 | F10: : | G10: 2 | H10: Szwajcaria | J10: 1 | K10: : | L10: 1 | M10: 4
A11: 23.06 | B11: 0.875 | D11: Szwajcaria | E11: 1 | F11: : | G11: 2 | H11: Niemcy | J11: 1 | K11: : | L11: 1 | M11: 1
A12: 23.06 | B12: 0.875 | D12: Szkocja | E12: 2 | F12: : | G12: 1 | H12: Węgry | J12: 0 | K12: : | L12: 1 | M12: 1
F14: Grupa B
A15: 15.06 | B15: 0.75 | D15: Hiszpania | E15: 1 | F15: : | G15: 0 | H15: Chorwacja | J15: 3 | K15: : | L15: 0 | M15: 4
A16: 15.06 | B16: 0.875 | D16: Włochy | E16: 1 | F16: : | G16: 0 | H16: Albania | J16: 2 | K16: : | L16: 1 | M16: 4
A17: 19.06 | B17: 0.625 | D17: Chorwacja | E17: 3 | F17: : | G17: 1 | H17: Albania | J17: 2 | K17: : | L17: 2 | M17: 0
A18: 20.06 | B18: 0.875 | D18: Hiszpania | E18: 2 | F18: : | G18: 1 | H18: Włochy | J18: 1 | K18: : | L18: 0 | M18: 4
A19: 24.06 | B19: 0.875 | D19: Albania | E19: 0 | F19: : | G19: 2 | H19: Hiszpania | J19: 0 | K19: : | L19: 1 | M19: 4
A20: 24.06 | B20: 0.875 | D20: Chorwacja | E20: 1 | F20: : | G20: 1 | H20: Włochy | J20: 1 | K20: : | L20: 1 | M20: 6
F22: Grupa C
A23: 16.06 | B23: 0.75 | D23: Słowenia | E23: 1 | F23: : | G23: 2 | H23: Dania | J23: 1 | K23: : | L23: 1 | M23: 1
A24: 16.06 | B24: 0.875 | D24: Serbia | E24: 0 | F24: : | G24: 2 | H24: Anglia | J24: 0 | K24: : | L24: 1 | M24: 4
A25: 20.06 | B25: 0.625 | D25: Słowenia | E25: 1 | F25: : | G25: 2 | H25: Serbia | J25: 1 | K25: : | L25: 1 | M25: 1
A26: 20.06 | B26: 0.75 | D26: Dania | E26: 0 | F26: : | G26: 2 | H26: Anglia | J26: 1 | K26: : | L26: 1 | M26: 0
A27: 25.06 | B27: 0.875 | D27: Angia | E27: 2 | F27: : | G27: 1 | H27: Słowenia | J27: 0 | K27: : | L27: 0 | M27: 0
A28: 25.06 | B28: 0.875 | D28: Dania | E28: 2 | F28: : | G28: 1 | H28: Serbia | J28: 0 | K28: : | L28: 0 | M28: 0
F30: Grupa D
A31: 16.06 | B31: 0.625 | D31: Polska | E31: 1 | F31: : | G31: 2 | H31: Holandia | J31: 1 | K31: : | L31: 2 | M31: 11
A32: 17.06 | B32: 0.875 | D32: Austria | E32: 1 | F32: : | G32: 2 | H32: Francja | J32: 0 | K32: : | L32: 1 | M32: 4
A33: 21.06 | B33: 0.75 | D33: Polska | E33: 1 | F33: : | G33: 2 | H33: Austria | J33: 1 | K33: : | L33: 3 | M33: 9
A34: 21.06 | B34: 0.875 | D34: Holandia | E34: 1 | F34: : | G34: 1 | H34: Francja | J34: 0 | K34: : | L34: 0 | M34: 4
A35: 25.06 | B35: 0.75 | D35: Holandia | E35: 2 | F35: : | G35: 2 | H35: Austria | J35: 2 | K35: : | L35: 3 | M35: 1
A36: 25.06 | B36: 0.75 | D36: Francja | E36: 3 | F36: : | G36: 1 | H36: Polska | J36: 1 | K36: : | L36: 1 | M36: 1
F38: Grupa E
A39: 17.06 | B39: 0.625 | D39: Rumunia | E39: 1 | F39: : | G39: 1 | H39: Ukraina | J39: 3 | K39: : | L39: 0 | M39: 0
A40: 17.06 | B40: 0.75 | D40: Belgia | E40: 2 | F40: : | G40: 0 | H40: Słowacja | J40: 0 | K40: : | L40: 1 | M40: 0
A41: 21.06 | B41: 0.625 | D41: Słowacja | E41: 1 | F41: : | G41: 2 | H41: Ukraina | J41: 1 | K41: : | L41: 2 | M41: 6
A42: 22.06 | B42: 0.875 | D42: Belgia | E42: 3 | F42: : | G42: 1 | H42: Rumunia | J42: 2 | K42: : | L42: 0 | M42: 4
A43: 26.06 | B43: 0.75 | D43: Słowacja | E43: 1 | F43: : | G43: 1 | H43: Rumunia | J43: 1 | K43: : | L43: 1 | M43: 6
A44: 26.06 | B44: 0.75 | D44: Ukraina | E44: 1 | F44: : | G44: 2 | H44: Belgia | J44: 0 | K44: : | L44: 0 | M44: 0
...

Sheet Grzegorz Cieślak
A1: Imię i nazwisko: Grzegorz Cieślak
A2: Typ na mistrza EURO 2024: | E2: Niemcy
F3: FAZA GRUPOWA | I3: Król strzelców: | L3: Kai Havertz
I4: Liczba goli: | L4: 6
A5: Data | B5: Godzina | F5: Typ | J5: Wynik meczu | M5: Liczba punktów
F6: Grupa A
A7: 14.06 | B7: 0.875 | D7: Niemcy | E7: 3 | F7: : | G7: 0 | H7: Szkocja | J7: 5 | K7: : | L7: 1 | M7: 3
A8: 15.06 | B8: 0.625 | D8: Węgry | E8: 1 | F8: : | G8: 0 | H8: Szwajcaria | J8: 1 | K8: : | L8: 3 | M8: 1
A9: 19.06 | B9: 0.75 | D9: Niemcy | E9: 3 | F9: : | G9: 1 | H9: Węgry | J9: 2 | K9: : | L9: 0 | M9: 4
A10: 19.06 | B10: 0.875 | D10: Szkocja | E10: 0 | F10: : | G10: 2 | H10: Szwajcaria | J10: 1 | K10: : | L10: 1 | M10: 0
A11: 23.06 | B11: 0.875 | D11: Szwajcaria | E11: 1 | F11: : | G11: 3 | H11: Niemcy | J11: 1 | K11: : | L11: 1 | M11: 1
A12: 23.06 | B12: 0.875 | D12: Szkocja | E12: 1 | F12: : | G12: 2 | H12: Węgry | J12: 0 | K12: : | L12: 1 | M12: 4
F14: Grupa B
A15: 15.06 | B15: 0.75 | D15: Hiszpania | E15: 2 | F15: : | G15: 0 | H15: Chorwacja | J15: 3 | K15: : | L15: 0 | M15: 4
A16: 15.06 | B16: 0.875 | D16: Włochy | E16: 4 | F16: : | G16: 0 | H16: Albania | J16: 2 | K16: : | L16: 1 | M16: 3
A17: 19.06 | B17: 0.625 | D17: Chorwacja | E17: 0 | F17: : | G17: 1 | H17: Albania | J17: 2 | K17: : | L17: 2 | M17: 0
A18: 20.06 | B18: 0.875 | D18: Hiszpania | E18: 0 | F18: : | G18: 1 | H18: Włochy | J18: 1 | K18: : | L18: 0 | M18: 0
A19: 24.06 | B19: 0.875 | D19: Albania | E19: 0 | F19: : | G19: 3 | H19: Hiszpania | J19: 0 | K19: : | L19: 1 | M19: 4
A20: 24.06 | B20: 0.875 | D20: Chorwacja | E20: 2 | F20: : | G20: 1 | H20: Włochy | J20: 1 | K20: : | L20: 1 | M20: 1
F22: Grupa C
A23: 16.06 | B23: 0.75 | D23: Słowania | E23: 1 | F23: : | G23: 0 | H23: Dania | J23: 1 | K23: : | L23: 1 | M23: 1
A24: 16.06 | B24: 0.875 | D24: Serbia | E24: 1 | F24: : | G24: 3 | H24: Anglia | J24: 0 | K24: : | L24: 1 | M24: 3
A25: 20.06 | B25: 0.625 | D25: Słowenia | E25: 0 | F25: : | G25: 0 | H25: Serbia | J25: 1 | K25: : | L25: 1 | M25: 4
A26: 20.06 | B26: 0.75 | D26: Dania | E26: 0 | F26: : | G26: 3 | H26: Anglia | J26: 1 | K26: : | L26: 1 | M26: 0
A27: 25.06 | B27: 0.875 | D27: Angia | E27: 1 | F27: : | G27: 0 | H27: Słowenia | J27: 0 | K27: : | L27: 0 | M27: 1
A28: 25.06 | B28: 0.875 | D28: Dania | E28: 2 | F28: : | G28: 1 | H28: Serbia | J28: 0 | K28: : | L28: 0 | M28: 0
F30: Grupa D
A31: 16.06 | B31: 0.625 | D31: Polska | E31: 0 | F31: : | G31: 3 | H31: Holandia | J31: 1 | K31: : | L31: 2 | M31: 8
A32: 17.06 | B32: 0.875 | D32: Austria | E32: 0 | F32: : | G32: 2 | H32: Francja | J32: 0 | K32: : | L32: 1 | M32: 4
A33: 21.06 | B33: 0.75 | D33: Polska | E33: 0 | F33: : | G33: 1 | H33: Austria | J33: 1 | K33: : | L33: 3 | M33: 8
A34: 21.06 | B34: 0.875 | D34: Holandia | E34: 1 | F34: : | G34: 0 | H34: Francja | J34: 0 | K34: : | L34: 0 | M34: 1
A35: 25.06 | B35: 0.75 | D35: Holandia | E35: 1 | F35: : | G35: 2 | H35: Austria | J35: 2 | K35: : | L35: 3 | M35: 4
A36: 25.06 | B36: 0.75 | D36: Francja | E36: 3 | F36: : | G36: 1 | H36: Polska | J36: 1 | K36: : | L36: 1 | M36: 1
F38: Grupa E
A39: 17.06 | B39: 0.625 | D39: Rumunia | E39: 1 | F39: : | G39: 2 | H39: Ukraina | J39: 3 | K39: : | L39: 0 | M39: 0
A40: 17.06 | B40: 0.75 | D40: Belgia | E40: 2 | F40: : | G40: 0 | H40: Słowacja | J40: 0 | K40: : | L40: 1 | M40: 0
A41: 21.06 | B41: 0.625 | D41: Słowacja | E41: 0 | F41: : | G41: 0 | H41: Ukraina | J41: 1 | K41: : | L41: 2 | M41: 0
A42: 22.06 | B42: 0.875 | D42: Belgia | E42: 1 | F42: : | G42: 0 | H42: Rumunia | J42: 2 | K42: : | L42: 0 | M42: 4
A43: 26.06 | B43: 0.75 | D43: Słowacja | E43: 1 | F43: : | G43: 2 | H43: Rumunia | J43: 1 | K43: : | L43: 1 | M43: 1
A44: 26.06 | B44: 0.75 | D44: Ukraina | E44: 1 | F44: : | G44: 3 | H44: Belgia | J44: 0 | K44: : | L44: 0 | M44: 0
...

Sheet Grzegorz Filipowicz
A1: Imię i nazwisko: Grzegorz Filipowicz
A2: Typ na mistrza EURO 2024: | E2: Anglia
F3: FAZA GRUPOWA | I3: Król strzelców: | L3: Harry Kane
I4: Liczba goli: | L4: 5
A5: Data | B5: Godzina | F5: Typ | J5: Wynik meczu | M5: Liczba punktów
F6: Grupa A
A7: 14.06 | B7: 0.875 | D7: Niemcy | E7: 2 | F7: : | G7: 0 | H7: Szkocja | J7: 5 | K7: : | L7: 1 | M7: 3
A8: 15.06 | B8: 0.625 | D8: Węgry | E8: 0 | F8: : | G8: 2 | H8: Szwajcaria | J8: 1 | K8: : | L8: 3 | M8: 4
A9: 19.06 | B9: 0.75 | D9: Niemcy | E9: 3 | F9: : | G9: 0 | H9: Węgry | J9: 2 | K9: : | L9: 0 | M9: 4
A10: 19.06 | B10: 0.875 | D10: Szkocja | E10: 0 | F10: : | G10: 1 | H10: Szwajcaria | J10: 1 | K10: : | L10: 1 | M10: 1
A11: 23.06 | B11: 0.875 | D11: Szwajcaria | E11: 1 | F11: : | G11: 1 | H11: Niemcy | J11: 1 | K11: : | L11: 1 | M11: 6
A12: 23.06 | B12: 0.875 | D12: Szkocja | E12: 1 | F12: : | G12: 0 | H12: Węgry | J12: 0 | K12: : | L12: 1 | M12: 0
F14: Grupa B
A15: 15.06 | B15: 0.75 | D15: Hiszpania | E15: 2 | F15: : | G15: 2 | H15: Chorwacja | J15: 3 | K15: : | L15: 0 | M15: 0
A16: 15.06 | B16: 0.875 | D16: Włochy | E16: 2 | F16: : | G16: 0 | H16: Albania | J16: 2 | K16: : | L16: 1 | M16: 4
A17: 19.06 | B17: 0.625 | D17: Chorwacja | E17: 2 | F17: : | G17: 1 | H17: Albania | J17: 2 | K17: : | L17: 2 | M17: 1
A18: 20.06 | B18: 0.875 | D18: Hiszpania | E18: 2 | F18: : | G18: 2 | H18: Włochy | J18: 1 | K18: : | L18: 0 | M18: 0
A19: 24.06 | B19: 0.875 | D19: Albania | E19: 0 | F19: : | G19: 2 | H19: Hiszpania | J19: 0 | K19: : | L19: 1 | M19: 4
A20: 24.06 | B20: 0.875 | D20: Chorwacja | E20: 2 | F20: : | G20: 2 | H20: Włochy | J20: 1 | K20: : | L20: 1 | M20: 4
F22: Grupa C
A23: 16.06 | B23: 0.75 | D23: Słowenia | E23: 1 | F23: : | G23: 2 | H23: Dania | J23: 1 | K23: : | L23: 1 | M23: 1
A24: 16.06 | B24: 0.875 | D24: Serbia | E24: 0 | F24: : | G24: 3 | H24: Anglia | J24: 0 | K24: : | L24: 1 | M24: 4
A25: 20.06 | B25: 0.625 | D25: Słowenia | E25: 1 | F25: : | G25: 1 | H25: Serbia | J25: 1 | K25: : | L25: 1 | M25: 6
A26: 20.06 | B26: 0.75 | D26: Dania | E26: 0 | F26: : | G26: 2 | H26: Anglia | J26: 1 | K26: : | L26: 1 | M26: 0
A27: 25.06 | B27: 0.875 | D27: Angia | E27: 2 | F27: : | G27: 1 | H27: Słowenia | J27: 0 | K27: : | L27: 0 | M27: 0
A28: 25.06 | B28: 0.875 | D28: Dania | E28: 1 | F28: : | G28: 0 | H28: Serbia | J28: 0 | K28: : | L28: 0 | M28: 1
F30: Grupa D
A31: 16.06 | B31: 0.625 | D31: Polska | E31: 1 | F31: : | G31: 1 | H31: Holandia | J31: 1 | K31: : | L31: 2 | M31: 1
A32: 17.06 | B32: 0.875 | D32: Austria | E32: 0 | F32: : | G32: 2 | H32: Francja | J32: 0 | K32: : | L32: 1 | M32: 4
A33: 21.06 | B33: 0.75 | D33: Polska | E33: 2 | F33: : | G33: 1 | H33: Austria | J33: 1 | K33: : | L33: 3 | M33: 0
A34: 21.06 | B34: 0.875 | D34: Holandia | E34: 1 | F34: : | G34: 2 | H34: Francja | J34: 0 | K34: : | L34: 0 | M34: 0
A35: 25.06 | B35: 0.75 | D35: Holandia | E35: 2 | F35: : | G35: 2 | H35: Austria | J35: 2 | K35: : | L35: 3 | M35: 1
A36: 25.06 | B36: 0.75 | D36: Francja | E36: 2 | F36: : | G36: 1 | H36: Polska | J36: 1 | K36: : | L36: 1 | M36: 1
F38: Grupa E
A39: 17.06 | B39: 0.625 | D39: Rumunia | E39: 0 | F39: : | G39: 0 | H39: Ukraina | J39: 3 | K39: : | L39: 0 | M39: 1
A40: 17.06 | B40: 0.75 | D40: Belgia | E40: 2 | F40: : | G40: 0 | H40: Słowacja | J40: 0 | K40: : | L40: 1 | M40: 0
A41: 21.06 | B41: 0.625 | D41: Słowacja | E41: 1 | F41: : | G41: 0 | H41: Ukraina | J41: 1 | K41: : | L41: 2 | M41: 1
A42: 22.06 | B42: 0.875 | D42: Belgia | E42: 1 | F42: : | G42: 0 | H42: Rumunia | J42: 2 | K42: : | L42: 0 | M42: 4
A43: 26.06 | B43: 0.75 | D43: Słowacja | E43: 2 | F43: : | G43: 1 | H43: Rumunia | J43: 1 | K43: : | L43: 1 | M43: 1
A44: 26.06 | B44: 0.75 | D44: Ukraina | E44: 0 | F44: : | G44: 2 | H44: Belgia | J44: 0 | K44: : | L44: 0 | M44: 1
...

Sheet Marcin Czarnecki
A1: Imię i nazwisko: Marcin Czarnecki
A2: Typ na mistrza EURO 2024: | E2: Anglia
F3: FAZA GRUPOWA | I3: Król strzelców: | L3: Harry Kane
I4: Liczba goli: | L4: 6
A5: Data | B5: Godzina | F5: Typ | J5: Wynik meczu | M5: Liczba punktów
F6: Grupa A
A7: 14.06 | B7: 0.875 | D7: Niemcy | E7: 2 | F7: : | G7: 0 | H7: Szkocja | J7: 5 | K7: : | L7: 1 | M7: 3
A8: 15.06 | B8: 0.625 | D8: Węgry | E8: 0 | F8: : | G8: 1 | H8: Szwajcaria | J8: 1 | K8: : | L8: 3 | M8: 3
A9: 19.06 | B9: 0.75 | D9: Niemcy | E9: 3 | F9: : | G9: 1 | H9: Węgry | J9: 2 | K9: : | L9: 0 | M9: 4
A10: 19.06 | B10: 0.875 | D10: Szkocja | E10: 1 | F10: : | G10: 2 | H10: Szwajcaria | J10: 1 | K10: : | L10: 1 | M10: 1
A11: 23.06 | B11: 0.875 | D11: Szwajcaria | E11: 0 | F11: : | G11: 1 | H11: Niemcy | J11: 1 | K11: : | L11: 1 | M11: 1
A12: 23.06 | B12: 0.875 | D12: Szkocja | E12: 1 | F12: : | G12: 0 | H12: Węgry | J12: 0 | K12: : | L12: 1 | M12: 0
A15: 15.06 | B15: 0.75 | D15: Hiszpania | E15: 0 | F15: : | G15: 0 | H15: Chorwacja | J15: 3 | K15: : | L15: 0 | M15: 1
A16: 15.06 | B16: 0.875 | D16: Włochy | E16: 2 | F16: : | G16: 0 | H16: Albania | J16: 2 | K16: : | L16: 1 | M16: 4
A17: 19.06 | B17: 0.625 | D17: Chorwacja | E17: 2 | F17: : | G17: 2 | H17: Albania | J17: 2 | K17: : | L17: 2 | M17: 6
A18: 20.06 | B18: 0.875 | D18: Hiszpania | E18: 1 | F18: : | G18: 1 | H18: Włochy | J18: 1 | K18: : | L18: 0 | M18: 1
A19: 24.06 | B19: 0.875 | D19: Albania | E19: 0 | F19: : | G19: 2 | H19: Hiszpania | J19: 0 | K19: : | L19: 1 | M19: 4
A20: 24.06 | B20: 0.875 | D20: Chorwacja | E20: 1 | F20: : | G20: 1 | H20: Włochy | J20: 1 | K20: : | L20: 1 | M20: 6
... A52: 26.06 | B52: 0.875 | D52: Gruzja | E52: 0 | F52: : | G52: 3 | H52: Portugalia | J52: 2 | K52: : | L52: 0 | M52: 0
F55: FAZA PUCHAROWA
F56: 1/8 FINAŁU
A57: 29.06 | B57: 0.75 | D57: Szwajcaria | E57: 1 | F57: : | G57: 1 | H57: Włochy | J57: 2 | K57: : | L57: 0 | M57: 0
A58: 29.06 | B58: 0.875 | D58: Niemcy | E58: 3 | F58: : | G58: 1 | H58: Dania | J58: 2 | K58: : | L58: 0 | M58: 8
A59: 30.06 | B59: 0.75 | D59: Anglia | E59: 1 | F59: : | G59: 0 | H59: Słowacja | J59: 1 | K59: : | L59: 1 | M59: 2
A60: 30.06 | B60: 0.875 | D60: Hiszpania | E60: 2 | F60: : | G60: 0 | H60: Gruzja | J60: 4 | K60: : | L60: 1 | M60: 6
A61: 01.07 | B61: 0.75 | D61: Francja | E61: 2 | F61: : | G61: 1 | H61: Belgia | J61: 1 | K61: : | L61: 0 | M61: 8
A62: 01.07 | B62: 0.875 | D62: Portugalia | E62: 2 | F62: : | G62: 1 | H62: Słowenia | J62: 0 | K62: : | L62: 0 | M62: 0
A63: 02.07 | B63: 0.75 | D63: Rumunia | E63: 1 | F63: : | G63: 2 | H63: Holandia | J63: 0 | K63: : | L63: 3 | M63: 6
A64: 02.07 | B64: 0.875 | D64: Austria | E64: 2 | F64: : | G64: 2 | H64: Turcja | J64: 1 | K64: : | L64: 2 | M64: 2
F65: 1/4 FINAŁU
A66: 05.07 | B66: 0.75 | D66: Hiszpania | E66: 1 | F66: : | G66: 1 | H66: Niemcy | J66: 1 | K66: : | L66: 1 | M66: 12 | O66: =_xlfn.TEXTJOIN(,,"update user_matches set team1_res=",E66,", team2_res=",G66," where match_id=",N66," and user_id= ",$N$65,";") -> update user_matches set team1_res=1, team2_res=1 where match_id= and user_id= ;
A67: 05.07 | B67: 0.875 | D67: Portugalia | E67: 0 | F67: : | G67: 1 | H67: Francja | J67: 0 | K67: : | L67: 0 | M67: 2 | O67: =_xlfn.TEXTJOIN(,,"update user_matches set team1_res=",E67,", team2_res=",G67," where match_id=",N67," and user_id= ",$N$65,";") -> update user_matches set team1_res=0, team2_res=1 where match_id= and user_id= ;
A68: 06.07 | B68: 0.75 | D68: Anglia | E68: 1 | F68: : | G68: 0 | H68: Szwajcaria | J68: 1 | K68: : | L68: 1 | M68: 2 | O68: =_xlfn.TEXTJOIN(,,"update user_matches set team1_res=",E68,", team2_res=",G68," where match_id=",N68," and user_id= ",$N$65,";") -> update user_matches set team1_res=1, team2_res=0 where match_id= and user_id= ;
A69: 06.07 | B69: 0.875 | D69: Holandia | E69: 2 | F69: : | G69: 1 | H69: Turcja | J69: 2 | K69: : | L69: 1 | M69: 12 | O69: =_xlfn.TEXTJOIN(,,"update user_matches set team1_res=",E69,", team2_res=",G69," where match_id=",N69," and user_id= ",$N$65,";") -> update user_matches set team1_res=2, team2_res=1 where match_id= and user_id= ;
F70: 1/2 FINAŁU
A71: 09.07 | B71: 0.875 | D71: Hiszpania | E71: 1 | F71: : | G71: 0 | H71: Francja | J71: 2 | K71: : | L71: 1 | M71: 12 | O71: =_xlfn.TEXTJOIN(,,"update user_matches set team1_res=",E71,", team2_res=",G71," where match_id=",N71," and user_id= ",$N$65,";") -> update user_matches set team1_res=1, team2_res=0 where match_id= and user_id= ;
A72: 10.07 | B72: 0.875 | D72: Holandia | E72: 1 | F72: : | G72: 1 | H72: Anglia | J72: 1 | K72: : | L72: 2 | M72: 3 | O72: =_xlfn.TEXTJOIN(,,"update user_matches set team1_res=",E72,", team2_res=",G72," where match_id=",N72," and user_id= ",$N$65,";") -> update user_matches set team1_res=1, team2_res=1 where match_id= and user_id= ;
F73: FINAŁ
A74: 14.07 | B74: 0.875 | D74: Hiszpania | E74: 1 | F74: : | G74: 2 | H74: Anglia | J74: 2 | K74: : | L74: 1 | M74: 0 | O74: =_xlfn.TEXTJOIN(,,"update user_matches set team1_res=",E74,", team2_res=",G74," where match_id=",N74," and user_id= ",$N$65,";") -> update user_matches set team1_res=1, team2_res=2 where match_id= and user_id= ;
M75: 20
...

Sheet Marcin Kupisz
A1: Imię i nazwisko: Marcin Kupisz
A2: Typ na mistrza EURO 2024: | E2: FRANCJA
F3: FAZA GRUPOWA | I3: Król strzelców: | L3: Kylian Mbappé
I4: Liczba goli: | L4: 6
A5: Data | B5: Godzina | F5: Typ | J5: Wynik meczu | M5: Liczba punktów
F6: Grupa A
A7: 14.06 | B7: 0.875 | D7: Niemcy | E7: 1 | F7: : | G7: 0 | H7: Szkocja | J7: 5 | K7: : | L7: 1 | M7: 3
A8: 15.06 | B8: 0.625 | D8: Węgry | E8: 0 | F8: : | G8: 0 | H8: Szwajcaria | J8: 1 | K8: : | L8: 3 | M8: 0
A9: 19.06 | B9: 0.75 | D9: Niemcy | E9: 3 | F9: : | G9: 0 | H9: Węgry | J9: 2 | K9: : | L9: 0 | M9: 4
A10: 19.06 | B10: 0.875 | D10: Szkocja | E10: 0 | F10: : | G10: 2 | H10: Szwajcaria | J10: 1 | K10: : | L10: 1 | M10: 0
A11: 23.06 | B11: 0.875 | D11: Szwajcaria | E11: 1 | F11: : | G11: 2 | H11: Niemcy | J11: 1 | K11: : | L11: 1 | M11: 1
A12: 23.06 | B12: 0.875 | D12: Szkocja | E12: 1 | F12: : | G12: 0 | H12: Węgry | J12: 0 | K12: : | L12: 1 | M12: 0
F14: Grupa B
A15: 15.06 | B15: 0.75 | D15: Hiszpania | E15: 2 | F15: : | G15: 2 | H15: Chorwacja | J15: 3 | K15: : | L15: 0 | M15: 0
A16: 15.06 | B16: 0.875 | D16: Włochy | E16: 2 | F16: : | G16: 0 | H16: Albania | J16: 2 | K16: : | L16: 1 | M16: 4
A17: 19.06 | B17: 0.625 | D17: Chorwacja | E17: 3 | F17: : | G17: 1 | H17: Albania | J17: 2 | K17: : | L17: 2 | M17: 0
A18: 20.06 | B18: 0.875 | D18: Hiszpania | E18: 2 | F18: : | G18: 1 | H18: Włochy | J18: 1 | K18: : | L18: 0 | M18: 4
A19: 24.06 | B19: 0.875 | D19: Albania | E19: 1 | F19: : | G19: 3 | H19: Hiszpania | J19: 0 | K19: : | L19: 1 | M19: 3
A20: 24.06 | B20: 0.875 | D20: Chorwacja | E20: 2 | F20: : | G20: 1 | H20: Włochy | J20: 1 | K20: : | L20: 1 | M20: 1
F22: Grupa C
A23: 16.06 | B23: 0.75 | D23: Słowania | E23: 1 | F23: : | G23: 3 | H23: Dania | J23: 1 | K23: : | L23: 1 | M23: 1
A24: 16.06 | B24: 0.875 | D24: Serbia | E24: 1 | F24: : | G24: 2 | H24: Anglia | J24: 0 | K24: : | L24: 1 | M24: 4
A25: 20.06 | B25: 0.625 | D25: Słowenia | E25: 1 | F25: : | G25: 1 | H25: Serbia | J25: 1 | K25: : | L25: 1 | M25: 6
A26: 20.06 | B26: 0.75 | D26: Dania | E26: 0 | F26: : | G26: 2 | H26: Anglia | J26: 1 | K26: : | L26: 1 | M26: 0
A27: 25.06 | B27: 0.875 | D27: Angia | E27: 2 | F27: : | G27: 0 | H27: Słowenia | J27: 0 | K27: : | L27: 0 | M27: 1
A28: 25.06 | B28: 0.875 | D28: Dania | E28: 1 | F28: : | G28: 0 | H28: Serbia | J28: 0 | K28: : | L28: 0 | M28: 1
F30: Grupa D
A31: 16.06 | B31: 0.625 | D31: Polska | E31: 2 | F31: : | G31: 1 | H31: Holandia | J31: 1 | K31: : | L31: 2 | M31: 0
A32: 17.06 | B32: 0.875 | D32: Austria | E32: 1 | F32: : | G32: 3 | H32: Francja | J32: 0 | K32: : | L32: 1 | M32: 3
A33: 21.06 | B33: 0.75 | D33: Polska | E33: 1 | F33: : | G33: 2 | H33: Austria | J33: 1 | K33: : | L33: 3 | M33: 9
A34: 21.06 | B34: 0.875 | D34: Holandia | E34: 1 | F34: : | G34: 2 | H34: Francja | J34: 0 | K34: : | L34: 0 | M34: 0
A35: 25.06 | B35: 0.75 | D35: Holandia | E35: 0 | F35: : | G35: 1 | H35: Austria | J35: 2 | K35: : | L35: 3 | M35: 4
A36: 25.06 | B36: 0.75 | D36: Francja | E36: 3 | F36: : | G36: 1 | H36: Polska | J36: 1 | K36: : | L36: 1 | M36: 1
F38: Grupa E
A39: 17.06 | B39: 0.625 | D39: Rumunia | E39: 1 | F39: : | G39: 1 | H39: Ukraina | J39: 3 | K39: : | L39: 0 | M39: 0
A40: 17.06 | B40: 0.75 | D40: Belgia | E40: 2 | F40: : | G40: 1 | H40: Słowacja | J40: 0 | K40: : | L40: 1 | M40: 1
A41: 21.06 | B41: 0.625 | D41: Słowacja | E41: 1 | F41: : | G41: 1 | H41: Ukraina | J41: 1 | K41: : | L41: 2 | M41: 1
A42: 22.06 | B42: 0.875 | D42: Belgia | E42: 2 | F42: : | G42: 1 | H42: Rumunia | J42: 2 | K42: : | L42: 0 | M42: 4
A43: 26.06 | B43: 0.75 | D43: Słowacja | E43: 1 | F43: : | G43: 2 | H43: Rumunia | J43: 1 | K43: : | L43: 1 | M43: 1
A44: 26.06 | B44: 0.75 | D44: Ukraina | E44: 1 | F44: : | G44: 2 | H44: Belgia | J44: 0 | K44: : | L44: 0 | M44: 0
...

Sheet Roman Kalinowski
A1: Imię i nazwisko: Roman Kalinowski
A2: Typ na mistrza EURO 2024: | E2: Anglia
F3: FAZA GRUPOWA | I3: Król strzelców: | L3: Harry Kane
I4: Liczba goli: | L4: 6
A5: Data | B5: Godzina | F5: Typ | J5: Wynik meczu | M5: Liczba punktów
F6: Grupa A
A7: 14.06 | B7: 0.875 | D7: Niemcy | E7: 2 | F7: : | G7: 0 | H7: Szkocja | J7: 5 | K7: : | L7: 1 | M7: 3
A8: 15.06 | B8: 0.625 | D8: Węgry | E8: 0 | F8: : | G8: 0 | H8: Szwajcaria | J8: 1 | K8: : | L8: 3 | M8: 0
A9: 19.06 | B9: 0.75 | D9: Niemcy | E9: 3 | F9: : | G9: 0 | H9: Węgry | J9: 2 | K9: : | L9: 0 | M9: 4
A10: 19.06 | B10: 0.875 | D10: Szkocja | E10: 2 | F10: : | G10: 3 | H10: Szwajcaria | J10: 1 | K10: : | L10: 1 | M10: 0
A11: 23.06 | B11: 0.875 | D11: Szwajcaria | E11: 1 | F11: : | G11: 2 | H11: Niemcy | J11: 1 | K11: : | L11: 1 | M11: 1
A12: 23.06 | B12: 0.875 | D12: Szkocja | E12: 1 | F12: : | G12: 0 | H12: Węgry | J12: 0 | K12: : | L12: 1 | M12: 0
F14: Grupa B
A15: 15.06 | B15: 0.75 | D15: Hiszpania | E15: 2 | F15: : | G15: 1 | H15: Chorwacja | J15: 3 | K15: : | L15: 0 | M15: 3
A16: 15.06 | B16: 0.875 | D16: Włochy | E16: 3 | F16: : | G16: 0 | H16: Albania | J16: 2 | K16: : | L16: 1 | M16: 3
A17: 19.06 | B17: 0.625 | D17: Chorwacja | E17: 2 | F17: : | G17: 0 | H17: Albania | J17: 2 | K17: : | L17: 2 | M17: 1
A18: 20.06 | B18: 0.875 | D18: Hiszpania | E18: 2 | F18: : | G18: 1 | H18: Włochy | J18: 1 | K18: : | L18: 0 | M18: 4
A19: 24.06 | B19: 0.875 | D19: Albania | E19: 0 | F19: : | G19: 2 | H19: Hiszpania | J19: 0 | K19: : | L19: 1 | M19: 4
A20: 24.06 | B20: 0.875 | D20: Chorwacja | E20: 1 | F20: : | G20: 2 | H20: Włochy | J20: 1 | K20: : | L20: 1 | M20: 1
F22: Grupa C
A23: 16.06 | B23: 0.75 | D23: Słowania | E23: 0 | F23: : | G23: 1 | H23: Dania | J23: 1 | K23: : | L23: 1 | M23: 1
A24: 16.06 | B24: 0.875 | D24: Serbia | E24: 0 | F24: : | G24: 3 | H24: Anglia | J24: 0 | K24: : | L24: 1 | M24: 4
A25: 20.06 | B25: 0.625 | D25: Słowenia | E25: 1 | F25: : | G25: 0 | H25: Serbia | J25: 1 | K25: : | L25: 1 | M25: 1
A26: 20.06 | B26: 0.75 | D26: Dania | E26: 1 | F26: : | G26: 2 | H26: Anglia | J26: 1 | K26: : | L26: 1 | M26: 1
A27: 25.06 | B27: 0.875 | D27: Angia | E27: 2 | F27: : | G27: 0 | H27: Słowenia | J27: 0 | K27: : | L27: 0 | M27: 1
A28: 25.06 | B28: 0.875 | D28: Dania | E28: 2 | F28: : | G28: 0 | H28: Serbia | J28: 0 | K28: : | L28: 0 | M28: 1
F30: Grupa D
A31: 16.06 | B31: 0.625 | D31: Polska | E31: 1 | F31: : | G31: 1 | H31: Holandia | J31: 1 | K31: : | L31: 2 | M31: 1
A32: 17.06 | B32: 0.875 | D32: Austria | E32: 0 | F32: : | G32: 1 | H32: Francja | J32: 0 | K32: : | L32: 1 | M32: 6
A33: 21.06 | B33: 0.75 | D33: Polska | E33: 1 | F33: : | G33: 0 | H33: Austria | J33: 1 | K33: : | L33: 3 | M33: 1
A34: 21.06 | B34: 0.875 | D34: Holandia | E34: 1 | F34: : | G34: 2 | H34: Francja | J34: 0 | K34: : | L34: 0 | M34: 0
A35: 25.06 | B35: 0.75 | D35: Holandia | E35: 2 | F35: : | G35: 1 | H35: Austria | J35: 2 | K35: : | L35: 3 | M35: 1
A36: 25.06 | B36: 0.75 | D36: Francja | E36: 2 | F36: : | G36: 0 | H36: Polska | J36: 1 | K36: : | L36: 1 | M36: 0
F38: Grupa E
A39: 17.06 | B39: 0.625 | D39: Rumunia | E39: 0 | F39: : | G39: 1 | H39: Ukraina | J39: 3 | K39: : | L39: 0 | M39: 0
A40: 17.06 | B40: 0.75 | D40: Belgia | E40: 2 | F40: : | G40: 0 | H40: Słowacja | J40: 0 | K40: : | L40: 1 | M40: 0
A41: 21.06 | B41: 0.625 | D41: Słowacja | E41: 0 | F41: : | G41: 1 | H41: Ukraina | J41: 1 | K41: : | L41: 2 | M41: 4
A42: 22.06 | B42: 0.875 | D42: Belgia | E42: 3 | F42: : | G42: 1 | H42: Rumunia | J42: 2 | K42: : | L42: 0 | M42: 4
A43: 26.06 | B43: 0.75 | D43: Słowacja | E43: 1 | F43: : | G43: 2 | H43: Rumunia | J43: 1 | K43: : | L43: 1 | M43: 1
A44: 26.06 | B44: 0.75 | D44: Ukraina | E44: 0 | F44: : | G44: 2 | H44: Belgia | J44: 0 | K44: : | L44: 0 | M44: 1
...

Sheet Konrad Pucułek
A1: Imię i nazwisko: Konrad Pucułek
A2: Typ na mistrza EURO 2024: | E2: Portugalia
F3: FAZA GRUPOWA | I3: Król strzelców: | L3: Jude Bellingham
I4: Liczba goli: | L4: 7
A5: Data | B5: Godzina | F5: Typ | J5: Wynik meczu | M5: Liczba punktów
F6: Grupa A
A7: 14.06 | B7: 0.875 | D7: Niemcy | E7: 2 | F7: : | G7: 1 | H7: Szkocja | J7: 5 | K7: : | L7: 1 | M7: 4
A8: 15.06 | B8: 0.625 | D8: Węgry | E8: 1 | F8: : | G8: 1 | H8: Szwajcaria | J8: 1 | K8: : | L8: 3 | M8: 1
A9: 19.06 | B9: 0.75 | D9: Niemcy | E9: 3 | F9: : | G9: 0 | H9: Węgry | J9: 2 | K9: : | L9: 0 | M9: 4
A10: 19.06 | B10: 0.875 | D10: Szkocja | E10: 1 | F10: : | G10: 3 | H10: Szwajcaria | J10: 1 | K10: : | L10: 1 | M10: 1
A11: 23.06 | B11: 0.875 | D11: Szwajcaria | E11: 1 | F11: : | G11: 2 | H11: Niemcy | J11: 1 | K11: : | L11: 1 | M11: 1
A12: 23.06 | B12: 0.875 | D12: Szkocja | E12: 2 | F12: : | G12: 2 | H12: Węgry | J12: 0 | K12: : | L12: 1 | M12: 0
A15: 15.06 | B15: 0.75 | D15: Hiszpania | E15: 1 | F15: : | G15: 0 | H15: Chorwacja | J15: 3 | K15: : | L15: 0 | M15: 4
A16: 15.06 | B16: 0.875 | D16: Włochy | E16: 3 | F16: : | G16: 0 | H16: Albania | J16: 2 | K16: : | L16: 1 | M16: 3
A17: 19.06 | B17: 0.625 | D17: Chorwacja | E17: 2 | F17: : | G17: 0 | H17: Albania | J17: 2 | K17: : | L17: 2 | M17: 1
A18: 20.06 | B18: 0.875 | D18: Hiszpania | E18: 1 | F18: : | G18: 1 | H18: Włochy | J18: 1 | K18: : | L18: 0 | M18: 1
A19: 24.06 | B19: 0.875 | D19: Albania | E19: 0 | F19: : | G19: 2 | H19: Hiszpania | J19: 0 | K19: : | L19: 1 | M19: 4
A20: 24.06 | B20: 0.875 | D20: Chorwacja | E20: 1 | F20: : | G20: 1 | H20: Włochy | J20: 1 | K20: : | L20: 1 | M20: 6
... A52: 26.06 | B52: 0.875 | D52: Gruzja | E52: 0 | F52: : | G52: 2 | H52: Portugalia | J52: 2 | K52: : | L52: 0 | M52: 0
F55: FAZA PUCHAROWA
F56: 1/8 FINAŁU
A57: 29.06 | B57: 0.75 | D57: Szwajcaria | E57: 2 | F57: : | G57: 1 | H57: Włochy | J57: 2 | K57: : | L57: 0 | M57: 8
A58: 29.06 | B58: 0.875 | D58: Niemcy | E58: 3 | F58: : | G58: 1 | H58: Dania | J58: 2 | K58: : | L58: 0 | M58: 8
A59: 30.06 | B59: 0.75 | D59: Anglia | E59: 1 | F59: : | G59: 0 | H59: Słowacja | J59: 1 | K59: : | L59: 1 | M59: 2
A60: 30.06 | B60: 0.875 | D60: Hiszpania | E60: 3 | F60: : | G60: 0 | H60: Gruzja | J60: 4 | K60: : | L60: 1 | M60: 8
A61: 01.07 | B61: 0.75 | D61: Francja | E61: 2 | F61: : | G61: 1 | H61: Belgia | J61: 1 | K61: : | L61: 0 | M61: 8
A62: 01.07 | B62: 0.875 | D62: Portugalia | E62: 2 | F62: : | G62: 0 | H62: Słowenia | J62: 0 | K62: : | L62: 0 | M62: 2
A63: 02.07 | B63: 0.75 | D63: Rumunia | E63: 0 | F63: : | G63: 2 | H63: Holandia | J63: 0 | K63: : | L63: 3 | M63: 8
A64: 02.07 | B64: 0.875 | D64: Austria | E64: 1 | F64: : | G64: 2 | H64: Turcja | J64: 1 | K64: : | L64: 2 | M64: 12
F65: 1/4 FINAŁU
A66: 05.07 | B66: 0.75 | D66: Hiszpania | E66: 0 | F66: : | G66: 1 | H66: Niemcy | J66: 1 | K66: : | L66: 1 | M66: 2 | O66: =_xlfn.TEXTJOIN(,,"update user_matches set team1_res=",E66,", team2_res=",G66," where match_id=",N66," and user_id= ",$N$65,";") -> update user_matches set team1_res=0, team2_res=1 where match_id= and user_id= ;
A67: 05.07 | B67: 0.875 | D67: Portugalia | E67: 1 | F67: : | G67: 0 | H67: Francja | J67: 0 | K67: : | L67: 0 | M67: 2 | O67: =_xlfn.TEXTJOIN(,,"update user_matches set team1_res=",E67,", team2_res=",G67," where match_id=",N67," and user_id= ",$N$65,";") -> update user_matches set team1_res=1, team2_res=0 where match_id= and user_id= ;
A68: 06.07 | B68: 0.75 | D68: Anglia | E68: 2 | F68: : | G68: 1 | H68: Szwajcaria | J68: 1 | K68: : | L68: 1 | M68: 2 | O68: =_xlfn.TEXTJOIN(,,"update user_matches set team1_res=",E68,", team2_res=",G68," where match_id=",N68," and user_id= ",$N$65,";") -> update user_matches set team1_res=2, team2_res=1 where match_id= and user_id= ;
A69: 06.07 | B69: 0.875 | D69: Holandia | E69: 3 | F69: : | G69: 1 | H69: Turcja | J69: 2 | K69: : | L69: 1 | M69: 8 | O69: =_xlfn.TEXTJOIN(,,"update user_matches set team1_res=",E69,", team2_res=",G69," where match_id=",N69," and user_id= ",$N$65,";") -> update user_matches set team1_res=3, team2_res=1 where match_id= and user_id= ;
F70: 1/2 FINAŁU
A71: 09.07 | B71: 0.875 | D71: Hiszpania | E71: 2 | F71: : | G71: 1 | H71: Francja | J71: 2 | K71: : | L71: 1 | M71: 18 | O71: =_xlfn.TEXTJOIN(,,"update user_matches set team1_res=",E71,", team2_res=",G71," where match_id=",N71," and user_id= ",$N$65,";") -> update user_matches set team1_res=2, team2_res=1 where match_id= and user_id= ;
A72: 10.07 | B72: 0.875 | D72: Holandia | E72: 1 | F72: : | G72: 2 | H72: Anglia | J72: 1 | K72: : | L72: 2 | M72: 18 | O72: =_xlfn.TEXTJOIN(,,"update user_matches set team1_res=",E72,", team2_res=",G72," where match_id=",N72," and user_id= ",$N$65,";") -> update user_matches set team1_res=1, team2_res=2 where match_id= and user_id= ;
F73: FINAŁ
A74: 14.07 | B74: 0.875 | D74: Hiszpania | E74: 1 | F74: : | G74: 2 | H74: Anglia | J74: 2 | K74: : | L74: 1 | M74: 0 | O74: =_xlfn.TEXTJOIN(,,"update user_matches set team1_res=",E74,", team2_res=",G74," where match_id=",N74," and user_id= ",$N$65,";") -> update user_matches set team1_res=1, team2_res=2 where match_id= and user_id= ;
A76: SUMA PUNKTÓW | M76: =SUM(M7:N75) -> 199

Sheet Łukasz Ostrowski
A1: Imię i nazwisko: Łukasz Ostrowski
A2: Typ na mistrza EURO 2024: | E2: Portugalia
F3: FAZA GRUPOWA | I3: Król strzelców: | L3: Mbappe
I4: Liczba goli: | L4: 6
A5: Data | B5: Godzina | F5: Typ | J5: Wynik meczu | M5: Liczba punktów
F6: Grupa A
A7: 14.06 | B7: 0.875 | D7: Niemcy | E7: 2 | F7: : | G7: 0 | H7: Szkocja | J7: 5 | K7: : | L7: 1 | M7: 3
A8: 15.06 | B8: 0.625 | D8: Węgry | E8: 1 | F8: : | G8: 1 | H8: Szwajcaria | J8: 1 | K8: : | L8: 3 | M8: 1
A9: 19.06 | B9: 0.75 | D9: Niemcy | E9: 3 | F9: : | G9: 1 | H9: Węgry | J9: 2 | K9: : | L9: 0 | M9: 4
A10: 19.06 | B10: 0.875 | D10: Szkocja | E10: 0 | F10: : | G10: 2 | H10: Szwajcaria | J10: 1 | K10: : | L10: 1 | M10: 0
A11: 23.06 | B11: 0.875 | D11: Szwajcaria | E11: 0 | F11: : | G11: 1 | H11: Niemcy | J11: 1 | K11: : | L11: 1 | M11: 1
A12: 23.06 | B12: 0.875 | D12: Szkocja | E12: 2 | F12: : | G12: 2 | H12: Węgry | J12: 0 | K12: : | L12: 1 | M12: 0
A15: 15.06 | B15: 0.75 | D15: Hiszpania | E15: 0 | F15: : | G15: 0 | H15: Chorwacja | J15: 3 | K15: : | L15: 0 | M15: 1
A16: 15.06 | B16: 0.875 | D16: Włochy | E16: 1 | F16: : | G16: 0 | H16: Albania | J16: 2 | K16: : | L16: 1 | M16: 4
A17: 19.06 | B17: 0.625 | D17: Chorwacja | E17: 2 | F17: : | G17: 1 | H17: Albania | J17: 2 | K17: : | L17: 2 | M17: 1
A18: 20.06 | B18: 0.875 | D18: Hiszpania | E18: 2 | F18: : | G18: 1 | H18: Włochy | J18: 1 | K18: : | L18: 0 | M18: 4
A19: 24.06 | B19: 0.875 | D19: Albania | E19: 1 | F19: : | G19: 2 | H19: Hiszpania | J19: 0 | K19: : | L19: 1 | M19: 4
A20: 24.06 | B20: 0.875 | D20: Chorwacja | E20: 1 | F20: : | G20: 1 | H20: Włochy | J20: 1 | K20: : | L20: 1 | M20: 6
... A50: 22.06 | B50: 0.75 | D50: Turcja | E50: 0 | F50: : | G50: 1 | H50: Portugalia | J50: 0 | K50: : | L50: 3 | M50: 4
A51: 26.06 | B51: 0.875 | D51: Czechy | E51: 2 | F51: : | G51: 2 | H51: Turcja | J51: 1 | K51: : | L51: 2
A52: 26.06 | B52: 0.875 | D52: Gruzja | E52: 1 | F52: : | G52: 2 | H52: Portugalia | J52: 2 | K52: : | L52: 0
F55: FAZA PUCHAROWA
F56: 1/8 FINAŁU
A57: 29.06 | B57: 0.75 | D57: Szwajcaria | E57: 1 | F57: : | G57: 1 | H57: Włochy | J57: 2 | K57: : | L57: 0 | M57: 0
A58: 29.06 | B58: 0.875 | D58: Niemcy | E58: 2 | F58: : | G58: 1 | H58: Dania | J58: 2 | K58: : | L58: 0 | M58: 8
A59: 30.06 | B59: 0.75 | D59: Anglia | E59: 2 | F59: : | G59: 0 | H59: Słowacja | J59: 1 | K59: : | L59: 1 | M59: 0
A60: 30.06 | B60: 0.875 | D60: Hiszpania | E60: 3 | F60: : | G60: 1 | H60: Gruzja | J60: 4 | K60: : | L60: 1 | M60: 8
A61: 01.07 | B61: 0.75 | D61: Francja | E61: 2 | F61: : | G61: 1 | H61: Belgia | J61: 1 | K61: : | L61: 0 | M61: 8
A62: 01.07 | B62: 0.875 | D62: Portugalia | E62: 1 | F62: : | G62: 0 | H62: Słowenia | J62: 0 | K62: : | L62: 0 | M62: 2
A63: 02.07 | B63: 0.75 | D63: Rumunia | E63: 0 | F63: : | G63: 1 | H63: Holandia | J63: 0 | K63: : | L63: 3 | M63: 8
A64: 02.07 | B64: 0.875 | D64: Austria | E64: 2 | F64: : | G64: 0 | H64: Turcja | J64: 1 | K64: : | L64: 2 | M64: 0
F65: 1/4 FINAŁU
A66: 05.07 | B66: 0.75 | D66: Hiszpania | E66: 2 | F66: : | G66: 2 | H66: Niemcy | J66: 1 | K66: : | L66: 1 | M66: 8
A67: 05.07 | B67: 0.875 | D67: Portugalia | E67: 0 | F67: : | G67: 1 | H67: Francja | J67: 0 | K67: : | L67: 0 | M67: 2
A68: 06.07 | B68: 0.75 | D68: Anglia | E68: 1 | F68: : | G68: 1 | H68: Szwajcaria | J68: 1 | K68: : | L68: 1 | M68: 12
A69: 06.07 | B69: 0.875 | D69: Holandia | E69: 3 | F69: : | G69: 2 | H69: Turcja | J69: 2 | K69: : | L69: 1 | M69: 8
F70: 1/2 FINAŁU
A71: 09.07 | B71: 0.875 | D71: Hiszpania | E71: 1 | F71: : | G71: 1 | H71: Francja | J71: 2 | K71: : | L71: 1 | M71: 3
A72: 10.07 | B72: 0.875 | D72: Holandia | E72: 0 | F72: : | G72: 1 | H72: Anglia | J72: 1 | K72: : | L72: 2 | M72: 12
F73: FINAŁ
...

Sheet Marek Szóstkiewicz
A1: Imię i nazwisko: Marek Szóstkiewicz
A2: Typ na mistrza EURO 2024: | E2: Anglia
F3: FAZA GRUPOWA | I3: Król strzelców: | L3: Harry Kane
I4: Liczba goli: | L4: 7
A5: Data | B5: Godzina | F5: Typ | J5: Wynik meczu | M5: Liczba punktów
F6: Grupa A
A7: 14.06 | B7: 0.875 | D7: Niemcy | E7: 1 | F7: : | G7: 1 | H7: Szkocja | J7: 5 | K7: : | L7: 1 | M7: 1
A8: 15.06 | B8: 0.625 | D8: Węgry | E8: 1 | F8: : | G8: 2 | H8: Szwajcaria | J8: 1 | K8: : | L8: 3 | M8: 4
A9: 19.06 | B9: 0.75 | D9: Niemcy | E9: 3 | F9: : | G9: 1 | H9: Węgry | J9: 2 | K9: : | L9: 0 | M9: 4
A10: 19.06 | B10: 0.875 | D10: Szkocja | E10: 1 | F10: : | G10: 1 | H10: Szwajcaria | J10: 1 | K10: : | L10: 1 | M10: 6
A11: 23.06 | B11: 0.875 | D11: Szwajcaria | E11: 1 | F11: : | G11: 2 | H11: Niemcy | J11: 1 | K11: : | L11: 1 | M11: 1
A12: 23.06 | B12: 0.875 | D12: Szkocja | E12: 1 | F12: : | G12: 1 | H12: Węgry | J12: 0 | K12: : | L12: 1 | M12: 1
F14: Grupa B
A15: 15.06 | B15: 0.75 | D15: Hiszpania | E15: 2 | F15: : | G15: 2 | H15: Chorwacja | J15: 3 | K15: : | L15: 0 | M15: 0
A16: 15.06 | B16: 0.875 | D16: Włochy | E16: 2 | F16: : | G16: 0 | H16: Albania | J16: 2 | K16: : | L16: 1 | M16: 4
A17: 19.06 | B17: 0.625 | D17: Chorwacja | E17: 2 | F17: : | G17: 1 | H17: Albania | J17: 2 | K17: : | L17: 2 | M17: 1
A18: 20.06 | B18: 0.875 | D18: Hiszpania | E18: 2 | F18: : | G18: 1 | H18: Włochy | J18: 1 | K18: : | L18: 0 | M18: 4
A19: 24.06 | B19: 0.875 | D19: Albania | E19: 1 | F19: : | G19: 3 | H19: Hiszpania | J19: 0 | K19: : | L19: 1 | M19: 3
A20: 24.06 | B20: 0.875 | D20: Chorwacja | E20: 2 | F20: : | G20: 1 | H20: Włochy | J20: 1 | K20: : | L20: 1 | M20: 1
F22: Grupa C
A23: 16.06 | B23: 0.75 | D23: Słowania | E23: 1 | F23: : | G23: 2 | H23: Dania | J23: 1 | K23: : | L23: 1 | M23: 1
A24: 16.06 | B24: 0.875 | D24: Serbia | E24: 0 | F24: : | G24: 2 | H24: Anglia | J24: 0 | K24: : | L24: 1 | M24: 4
A25: 20.06 | B25: 0.625 | D25: Słowenia | E25: 1 | F25: : | G25: 0 | H25: Serbia | J25: 1 | K25: : | L25: 1 | M25: 1
A26: 20.06 | B26: 0.75 | D26: Dania | E26: 1 | F26: : | G26: 2 | H26: Anglia | J26: 1 | K26: : | L26: 1 | M26: 1
A27: 25.06 | B27: 0.875 | D27: Angia | E27: 2 | F27: : | G27: 1 | H27: Słowenia | J27: 0 | K27: : | L27: 0 | M27: 0
A28: 25.06 | B28: 0.875 | D28: Dania | E28: 2 | F28: : | G28: 1 | H28: Serbia | J28: 0 | K28: : | L28: 0 | M28: 0
F30: Grupa D
A31: 16.06 | B31: 0.625 | D31: Polska | E31: 1 | F31: : | G31: 3 | H31: Holandia | J31: 1 | K31: : | L31: 2 | M31: 9
A32: 17.06 | B32: 0.875 | D32: Austria | E32: 0 | F32: : | G32: 1 | H32: Francja | J32: 0 | K32: : | L32: 1 | M32: 6
A33: 21.06 | B33: 0.75 | D33: Polska | E33: 0 | F33: : | G33: 1 | H33: Austria | J33: 1 | K33: : | L33: 3 | M33: 8
A34: 21.06 | B34: 0.875 | D34: Holandia | E34: 1 | F34: : | G34: 2 | H34: Francja | J34: 0 | K34: : | L34: 0 | M34: 0
A35: 25.06 | B35: 0.75 | D35: Holandia | E35: 1 | F35: : | G35: 1 | H35: Austria | J35: 2 | K35: : | L35: 3 | M35: 0
A36: 25.06 | B36: 0.75 | D36: Francja | E36: 2 | F36: : | G36: 1 | H36: Polska | J36: 1 | K36: : | L36: 1 | M36: 1
F38: Grupa E
A39: 17.06 | B39: 0.625 | D39: Rumunia | E39: 1 | F39: : | G39: 1 | H39: Ukraina | J39: 3 | K39: : | L39: 0 | M39: 0
A40: 17.06 | B40: 0.75 | D40: Belgia | E40: 1 | F40: : | G40: 0 | H40: Słowacja | J40: 0 | K40: : | L40: 1 | M40: 0
A41: 21.06 | B41: 0.625 | D41: Słowacja | E41: 2 | F41: : | G41: 2 | H41: Ukraina | J41: 1 | K41: : | L41: 2 | M41: 1
A42: 22.06 | B42: 0.875 | D42: Belgia | E42: 1 | F42: : | G42: 0 | H42: Rumunia | J42: 2 | K42: : | L42: 0 | M42: 4
A43: 26.06 | B43: 0.75 | D43: Słowacja | E43: 1 | F43: : | G43: 0 | H43: Rumunia | J43: 1 | K43: : | L43: 1 | M43: 1
A44: 26.06 | B44: 0.75 | D44: Ukraina | E44: 1 | F44: : | G44: 2 | H44: Belgia | J44: 0 | K44: : | L44: 0 | M44: 0
...

Sheet Monika Bugajska
A1: Imię i nazwisko: Monika Bugajska
A2: Typ na mistrza EURO 2024: | E2: Francja
F3: FAZA GRUPOWA | I3: Król strzelców: | L3: Mbappe
I4: Liczba goli: | L4: 9
A5: Data | B5: Godzina | F5: Typ | J5: Wynik meczu | M5: Liczba punktów
F6: Grupa A
A7: 14.06 | B7: 0.875 | D7: Niemcy | E7: 1 | F7: : | G7: 0 | H7: Szkocja | J7: 5 | K7: : | L7: 1 | M7: 3
A8: 15.06 | B8: 0.625 | D8: Węgry | E8: 0 | F8: : | G8: 1 | H8: Szwajcaria | J8: 1 | K8: : | L8: 3 | M8: 3
A9: 19.06 | B9: 0.75 | D9: Niemcy | E9: 2 | F9: : | G9: 0 | H9: Węgry | J9: 2 | K9: : | L9: 0 | M9: 6
A10: 19.06 | B10: 0.875 | D10: Szkocja | E10: 0 | F10: : | G10: 1 | H10: Szwajcaria | J10: 1 | K10: : | L10: 1 | M10: 1
A11: 23.06 | B11: 0.875 | D11: Szwajcaria | E11: 1 | F11: : | G11: 3 | H11: Niemcy | J11: 1 | K11: : | L11: 1 | M11: 1
A12: 23.06 | B12: 0.875 | D12: Szkocja | E12: 1 | F12: : | G12: 1 | H12: Węgry | J12: 0 | K12: : | L12: 1 | M12: 1
F14: Grupa B
A15: 15.06 | B15: 0.75 | D15: Hiszpania | E15: 3 | F15: : | G15: 1 | H15: Chorwacja | J15: 3 | K15: : | L15: 0 | M15: 4
A16: 15.06 | B16: 0.875 | D16: Włochy | E16: 2 | F16: : | G16: 1 | H16: Albania | J16: 2 | K16: : | L16: 1 | M16: 6
A17: 19.06 | B17: 0.625 | D17: Chorwacja | E17: 2 | F17: : | G17: 1 | H17: Albania | J17: 2 | K17: : | L17: 2 | M17: 1
A18: 20.06 | B18: 0.875 | D18: Hiszpania | E18: 3 | F18: : | G18: 2 | H18: Włochy | J18: 1 | K18: : | L18: 0 | M18: 4
A19: 24.06 | B19: 0.875 | D19: Albania | E19: 0 | F19: : | G19: 2 | H19: Hiszpania | J19: 0 | K19: : | L19: 1 | M19: 4
A20: 24.06 | B20: 0.875 | D20: Chorwacja | E20: 1 | F20: : | G20: 2 | H20: Włochy | J20: 1 | K20: : | L20: 1 | M20: 1
F22: Grupa C
A23: 16.06 | B23: 0.75 | D23: Słowania | E23: 1 | F23: : | G23: 1 | H23: Dania | J23: 1 | K23: : | L23: 1 | M23: 6
A24: 16.06 | B24: 0.875 | D24: Serbia | E24: 1 | F24: : | G24: 3 | H24: Anglia | J24: 0 | K24: : | L24: 1 | M24: 3
A25: 20.06 | B25: 0.625 | D25: Słowenia | E25: 0 | F25: : | G25: 1 | H25: Serbia | J25: 1 | K25: : | L25: 1 | M25: 1
A26: 20.06 | B26: 0.75 | D26: Dania | E26: 0 | F26: : | G26: 2 | H26: Anglia | J26: 1 | K26: : | L26: 1 | M26: 0
A27: 25.06 | B27: 0.875 | D27: Angia | E27: 3 | F27: : | G27: 1 | H27: Słowenia | J27: 0 | K27: : | L27: 0 | M27: 0
A28: 25.06 | B28: 0.875 | D28: Dania | E28: 2 | F28: : | G28: 1 | H28: Serbia | J28: 0 | K28: : | L28: 0 | M28: 0
F30: Grupa D
A31: 16.06 | B31: 0.625 | D31: Polska | E31: 0 | F31: : | G31: 1 | H31: Holandia | J31: 1 | K31: : | L31: 2 | M31: 9
A32: 17.06 | B32: 0.875 | D32: Austria | E32: 1 | F32: : | G32: 2 | H32: Francja | J32: 0 | K32: : | L32: 1 | M32: 4
A33: 21.06 | B33: 0.75 | D33: Polska | E33: 1 | F33: : | G33: 2 | H33: Austria | J33: 1 | K33: : | L33: 3 | M33: 9
A34: 21.06 | B34: 0.875 | D34: Holandia | E34: 1 | F34: : | G34: 3 | H34: Francja | J34: 0 | K34: : | L34: 0 | M34: 0
A35: 25.06 | B35: 0.75 | D35: Holandia | E35: 2 | F35: : | G35: 0 | H35: Austria | J35: 2 | K35: : | L35: 3 | M35: 1
A36: 25.06 | B36: 0.75 | D36: Francja | E36: 2 | F36: : | G36: 0 | H36: Polska | J36: 1 | K36: : | L36: 1 | M36: 0
F38: Grupa E
A39: 17.06 | B39: 0.625 | D39: Rumunia | E39: 1 | F39: : | G39: 0 | H39: Ukraina | J39: 3 | K39: : | L39: 0 | M39: 4
A40: 17.06 | B40: 0.75 | D40: Belgia | E40: 1 | F40: : | G40: 1 | H40: Słowacja | J40: 0 | K40: : | L40: 1 | M40: 1
A41: 21.06 | B41: 0.625 | D41: Słowacja | E41: 2 | F41: : | G41: 0 | H41: Ukraina | J41: 1 | K41: : | L41: 2 | M41: 0
A42: 22.06 | B42: 0.875 | D42: Belgia | E42: 2 | F42: : | G42: 1 | H42: Rumunia | J42: 2 | K42: : | L42: 0 | M42: 4
A43: 26.06 | B43: 0.75 | D43: Słowacja | E43: 2 | F43: : | G43: 1 | H43: Rumunia | J43: 1 | K43: : | L43: 1 | M43: 1
A44: 26.06 | B44: 0.75 | D44: Ukraina | E44: 1 | F44: : | G44: 3 | H44: Belgia | J44: 0 | K44: : | L44: 0 | M44: 0
...

Sheet Mariusz Tarnowski
A1: Imię i nazwisko: MARIUSZ TARNOWSKI (13.06.2024)
A2: Typ na mistrza EURO 2024: | E2: ANGLIA
F3: FAZA GRUPOWA | I3: Król strzelców: | L3: HARRY KANE
I4: Liczba goli: | L4: 10
A5: Data | B5: Godzina | F5: Typ | J5: Wynik meczu | M5: Liczba punktów
F6: Grupa A
A7: 14.06 | B7: 0.875 | D7: Niemcy | E7: 2 | F7: : | G7: 1 | H7: Szkocja | J7: 5 | K7: : | L7: 1 | M7: 4
A8: 15.06 | B8: 0.625 | D8: Węgry | E8: 0 | F8: : | G8: 0 | H8: Szwajcaria | J8: 1 | K8: : | L8: 3 | M8: 0
A9: 19.06 | B9: 0.75 | D9: Niemcy | E9: 3 | F9: : | G9: 0 | H9: Węgry | J9: 2 | K9: : | L9: 0 | M9: 4
A10: 19.06 | B10: 0.875 | D10: Szkocja | E10: 2 | F10: : | G10: 3 | H10: Szwajcaria | J10: 1 | K10: : | L10: 1 | M10: 0
A11: 23.06 | B11: 0.875 | D11: Szwajcaria | E11: 3 | F11: : | G11: 1 | H11: Niemcy | J11: 1 | K11: : | L11: 1 | M11: 1
A12: 23.06 | B12: 0.875 | D12: Szkocja | E12: 1 | F12: : | G12: 0 | H12: Węgry | J12: 0 | K12: : | L12: 1 | M12: 0
F14: Grupa B
A15: 15.06 | B15: 0.75 | D15: Hiszpania | E15: 2 | F15: : | G15: 1 | H15: Chorwacja | J15: 3 | K15: : | L15: 0 | M15: 3
A16: 15.06 | B16: 0.875 | D16: Włochy | E16: 2 | F16: : | G16: 0 | H16: Albania | J16: 2 | K16: : | L16: 1 | M16: 4
A17: 19.06 | B17: 0.625 | D17: Chorwacja | E17: 3 | F17: : | G17: 1 | H17: Albania | J17: 2 | K17: : | L17: 2 | M17: 0
A18: 20.06 | B18: 0.875 | D18: Hiszpania | E18: 2 | F18: : | G18: 1 | H18: Włochy | J18: 1 | K18: : | L18: 0 | M18: 4
A19: 24.06 | B19: 0.875 | D19: Albania | E19: 1 | F19: : | G19: 4 | H19: Hiszpania | J19: 0 | K19: : | L19: 1 | M19: 3
A20: 24.06 | B20: 0.875 | D20: Chorwacja | E20: 2 | F20: : | G20: 2 | H20: Włochy | J20: 1 | K20: : | L20: 1 | M20: 4
F22: Grupa C
A23: 16.06 | B23: 0.75 | D23: Słowania | E23: 0 | F23: : | G23: 0 | H23: Dania | J23: 1 | K23: : | L23: 1 | M23: 4
A24: 16.06 | B24: 0.875 | D24: Serbia | E24: 0 | F24: : | G24: 3 | H24: Anglia | J24: 0 | K24: : | L24: 1 | M24: 4
A25: 20.06 | B25: 0.625 | D25: Słowenia | E25: 1 | F25: : | G25: 1 | H25: Serbia | J25: 1 | K25: : | L25: 1 | M25: 6
A26: 20.06 | B26: 0.75 | D26: Dania | E26: 2 | F26: : | G26: 0 | H26: Anglia | J26: 1 | K26: : | L26: 1 | M26: 0
A27: 25.06 | B27: 0.875 | D27: Angia | E27: 0 | F27: : | G27: 1 | H27: Słowenia | J27: 0 | K27: : | L27: 0 | M27: 1
A28: 25.06 | B28: 0.875 | D28: Dania | E28: 2 | F28: : | G28: 0 | H28: Serbia | J28: 0 | K28: : | L28: 0 | M28: 1
F30: Grupa D
A31: 16.06 | B31: 0.625 | D31: Polska | E31: 1 | F31: : | G31: 3 | H31: Holandia | J31: 1 | K31: : | L31: 2 | M31: 9
A32: 17.06 | B32: 0.875 | D32: Austria | E32: 0 | F32: : | G32: 3 | H32: Francja | J32: 0 | K32: : | L32: 1 | M32: 4
A33: 21.06 | B33: 0.75 | D33: Polska | E33: 1 | F33: : | G33: 1 | H33: Austria | J33: 1 | K33: : | L33: 3 | M33: 1
A34: 21.06 | B34: 0.875 | D34: Holandia | E34: 2 | F34: : | G34: 0 | H34: Francja | J34: 0 | K34: : | L34: 0 | M34: 1
A35: 25.06 | B35: 0.75 | D35: Holandia | E35: 3 | F35: : | G35: 2 | H35: Austria | J35: 2 | K35: : | L35: 3 | M35: 0
A36: 25.06 | B36: 0.75 | D36: Francja | E36: 4 | F36: : | G36: 0 | H36: Polska | J36: 1 | K36: : | L36: 1 | M36: 0
F38: Grupa E
A39: 17.06 | B39: 0.625 | D39: Rumunia | E39: 0 | F39: : | G39: 1 | H39: Ukraina | J39: 3 | K39: : | L39: 0 | M39: 0
A40: 17.06 | B40: 0.75 | D40: Belgia | E40: 2 | F40: : | G40: 0 | H40: Słowacja | J40: 0 | K40: : | L40: 1 | M40: 0
A41: 21.06 | B41: 0.625 | D41: Słowacja | E41: 2 | F41: : | G41: 1 | H41: Ukraina | J41: 1 | K41: : | L41: 2 | M41: 0
A42: 22.06 | B42: 0.875 | D42: Belgia | E42: 2 | F42: : | G42: 2 | H42: Rumunia | J42: 2 | K42: : | L42: 0 | M42: 1
A43: 26.06 | B43: 0.75 | D43: Słowacja | E43: 1 | F43: : | G43: 1 | H43: Rumunia | J43: 1 | K43: : | L43: 1 | M43: 6
A44: 26.06 | B44: 0.75 | D44: Ukraina | E44: 1 | F44: : | G44: 3 | H44: Belgia | J44: 0 | K44: : | L44: 0 | M44: 0
...

Sheet Milena Strąk-Małecka
A1: Imię i nazwisko: Milena Strąk-Małecka
A2: Typ na mistrza EURO 2024: | E2: Niemcy
F3: FAZA GRUPOWA | I3: Król strzelców: | L3: Harry Kane
I4: Liczba goli: | L4: 7
A5: Data | B5: Godzina | F5: Typ | J5: Wynik meczu | M5: Liczba punktów
F6: Grupa A
A7: 14.06 | B7: 0.875 | D7: Niemcy | E7: 3 | F7: : | G7: 0 | H7: Szkocja | J7: 5 | K7: : | L7: 1 | M7: 3
A8: 15.06 | B8: 0.625 | D8: Węgry | E8: 2 | F8: : | G8: 1 | H8: Szwajcaria | J8: 1 | K8: : | L8: 3 | M8: 0
A9: 19.06 | B9: 0.75 | D9: Niemcy | E9: 2 | F9: : | G9: 1 | H9: Węgry | J9: 2 | K9: : | L9: 0 | M9: 4
A10: 19.06 | B10: 0.875 | D10: Szkocja | E10: 2 | F10: : | G10: 1 | H10: Szwajcaria | J10: 1 | K10: : | L10: 1 | M10: 1
A11: 23.06 | B11: 0.875 | D11: Szwajcaria | E11: 0 | F11: : | G11: 3 | H11: Niemcy | J11: 1 | K11: : | L11: 1 | M11: 0
A12: 23.06 | B12: 0.875 | D12: Szkocja | E12: 2 | F12: : | G12: 0 | H12: Węgry | J12: 0 | K12: : | L12: 1 | M12: 0
F14: Grupa B
A15: 15.06 | B15: 0.75 | D15: Hiszpania | E15: 2 | F15: : | G15: 1 | H15: Chorwacja | J15: 3 | K15: : | L15: 0 | M15: 3
A16: 15.06 | B16: 0.875 | D16: Włochy | E16: 3 | F16: : | G16: 0 | H16: Albania | J16: 2 | K16: : | L16: 1 | M16: 3
A17: 19.06 | B17: 0.625 | D17: Chorwacja | E17: 2 | F17: : | G17: 0 | H17: Albania | J17: 2 | K17: : | L17: 2 | M17: 1
A18: 20.06 | B18: 0.875 | D18: Hiszpania | E18: 1 | F18: : | G18: 2 | H18: Włochy | J18: 1 | K18: : | L18: 0 | M18: 1
A19: 24.06 | B19: 0.875 | D19: Albania | E19: 0 | F19: : | G19: 2 | H19: Hiszpania | J19: 0 | K19: : | L19: 1 | M19: 4
A20: 24.06 | B20: 0.875 | D20: Chorwacja | E20: 0 | F20: : | G20: 2 | H20: Włochy | J20: 1 | K20: : | L20: 1 | M20: 0
F22: Grupa C
